<?xml version="1.0" ?>
<!-- =================================================================================== -->
<!-- |    This document was autogenerated by xacro from robot.xacro                    | -->
<!-- |    EDITING THIS FILE BY HAND IS NOT RECOMMENDED                                 | -->
<!-- =================================================================================== -->
<robot name="ackerman">
  <link name="body_link">
    <visual>
      <origin rpy="0.0 0.0 0.0" xyz="0.1 0.0 0.0"/>
      <geometry>
        <box size="0.26 0.09 0.04"/>
      </geometry>
    </visual>
    <collision name="body_collision">
      <origin rpy="0.0 0.0 0.0" xyz="0.09 0.0 0.03"/>
      <geometry>
        <cylinder length="0.1" radius="0.15"/>
      </geometry>
    </collision>
    <inertial>
      <origin rpy="0.0 0.0 0.0" xyz="0.0 0.0 0.0"/>
      <mass value="0.1"/>
      <inertia ixx="0.0001" ixy="0" ixz="0" iyy="0.0001" iyz="0" izz="0.0001"/>
    </inertial>
  </link>
  <joint name="laserbase_joint" type="fixed">
    <parent link="body_link"/>
    <child link="laserbase_link"/>
    <origin rpy="0 0 0" xyz="0.12 0 0.035"/>
  </joint>
  <link name="laserbase_link">
    <visual>
      <origin rpy="0 0 0" xyz="0 0 0"/>
      <geometry>
        <cylinder length="0.03" radius="0.02"/>
      </geometry>
    </visual>
    <collision>
      <origin rpy="0 0 0" xyz="0 0 0"/>
      <geometry>
        <cylinder length="0.03" radius="0.02"/>
      </geometry>
    </collision>
    <inertial>
      <origin rpy="0 0 0" xyz="0 0 0"/>
      <mass value="1.0"/>
      <inertia ixx="0.01" ixy="0" ixz="0" iyy="0.01" iyz="0" izz="0.01"/>
    </inertial>
  </link>
  <joint name="laser_joint" type="fixed">
    <parent link="laserbase_link"/>
    <child link="laser_link"/>
    <origin rpy="0 0 0" xyz="0 0 0.03"/>
  </joint>
  <link name="laser_link">
    <visual>
      <origin rpy="0 0 0" xyz="0 0 0"/>
      <geometry>
        <cylinder length="0.03" radius="0.02"/>
      </geometry>
    </visual>
    <collision>
      <origin rpy="0 0 0" xyz="0 0 0"/>
      <geometry>
        <cylinder length="0.03" radius="0.02"/>
      </geometry>
    </collision>
    <inertial>
      <origin rpy="0 0 0" xyz="0 0 0"/>
      <mass value="1.0"/>
      <inertia ixx="0.01" ixy="0" ixz="0" iyy="0.01" iyz="0" izz="0.01"/>
    </inertial>
  </link>
  <joint name="wheelRL_continuous" type="continuous">
    <parent link="body_link"/>
    <child link="wheelRL_link"/>
    <axis xyz="0 1 0"/>
  </joint>
  <link name="wheelRL_link">
    <visual>
      <origin rpy="1.570796 0 0" xyz="0 0.075 -0.015"/>
      <geometry>
        <cylinder length="0.026" radius="0.03"/>
      </geometry>
    </visual>
    <collision>
      <origin rpy="1.570796 0 0" xyz="0 0.075 -0.015"/>
      <geometry>
        <cylinder length="0.026" radius="0.03"/>
      </geometry>
    </collision>
    <inertial>
      <origin rpy="0 0 0" xyz="0 0 0"/>
      <mass value="1.0"/>
      <inertia ixx="0.01" ixy="0" ixz="0" iyy="0.01" iyz="0" izz="0.01"/>
    </inertial>
  </link>
  <joint name="wheelRR_continuous" type="continuous">
    <parent link="body_link"/>
    <child link="wheelRR_link"/>
    <axis xyz="0 1 0"/>
  </joint>
  <link name="wheelRR_link">
    <visual>
      <origin rpy="1.570796 0 0" xyz="0 -0.075 -0.015"/>
      <geometry>
        <cylinder length="0.026" radius="0.03"/>
      </geometry>
    </visual>
    <collision>
      <origin rpy="1.570796 0 0" xyz="0 -0.075 -0.015"/>
      <geometry>
        <cylinder length="0.026" radius="0.03"/>
      </geometry>
    </collision>
    <inertial>
      <origin rpy="0 0 0" xyz="0 0 0"/>
      <mass value="1.0"/>
      <inertia ixx="0.01" ixy="0" ixz="0" iyy="0.01" iyz="0" izz="0.01"/>
    </inertial>
  </link>


</robot>
